File: output_whole_data.csv
<beam_data>
No,i,j,length(m),I(m4),K(cm3),initial_eq_beam_stiff_ratio_i,initial_eq_beam_stiff_ratio_j,eq_beam_stiff_ratio_i,eq_beam_stiff_ratio_j,phai,phai2,calc_phai,Ci(kNm),Cj(kNm),beam_category,beam_direction,beam_belong_story,M0(kNm),Q0(kN),unit_weight(kg/m),weight(kg),Z(m3),Zp(m3),initial_B(mm),initial_H(mm),initial_t1(mm),initial_t2(mm),phase1_B(mm),phase1_H(mm),phase1_t1(mm),phase1_t2(mm),phase2_B(mm),phase2_H(mm),phase2_t1(mm),phase2_t2(mm),phase3_B(mm),phase3_H(mm),phase3_t1(mm),phase3_t2(mm),B(mm),H(mm),t1(mm),t2(mm),init_group,boundary_i,boundary_j,Mp(kNm),M_Lx_i(kNm),M_Lx_j(kNm),M_Lx0(kNm),M_Ly_i(kNm),M_Ly_j(kNm),M_Ly0(kNm),M_Sx_i(kNm),M_Sx_j(kNm),M_Sy_i(kNm),M_Sy_j(kNm),Q_Lx_i(kN),Q_Lx_j(kN),Q_Ly_i(kN),Q_Ly_j(kN),Q_Sx(kN),Q_Sy(kN),N_Lx(kN),N_Ly(kN),N_Sx(kN),N_Sy(kN),ML(kNm),QL(kN),Ms(kNm),Qs(kN),beam_deflection_x(m),beam_deflection_y(m),beam_deflection_x(after_revision)(m),beam_deflection_y(after_revision)(m),beam_bending_stress(N/mm2)(long),beam_shear_stress(N/mm2)(long),beam_bending_stress(N/mm2)(short),beam_shear_stress(N/mm2)(short)
1,1,2,5.64,         0,284552.85,0.00,0.00,0.00,0.00,1.2,1.3,[],41.71,41.71,BB,Y,1,65.69,37.71,0.00,0.00,         0,         0,0,0,0,0,[],[],[],[],[],[],[],[],0,0,0,0,0,0,0,0,[],fix,fix,0.00,0.00,0.00,0.00,-7.32,52.66,0.00,0.00,0.00,193.28,140.78,0.00,0.00,29.67,45.75,0.00,59.23,0.00,0.00,0.00,0.00,52.66,45.75,200.60,104.98,[],0,[],0,0.00,0.00,0.00,0.00
2,2,3,5.70,         0,284552.85,0.00,0.00,0.00,0.00,1.2,1.3,[],42.94,42.94,BB,Y,1,67.64,38.40,0.00,0.00,         0,         0,0,0,0,0,[],[],[],[],[],[],[],[],0,0,0,0,0,0,0,0,[],fix,fix,0.00,0.00,0.00,0.00,-52.84,43.25,0.00,0.00,0.00,139.29,139.58,0.00,0.00,40.08,36.71,0.00,48.92,0.00,0.00,0.00,0.00,52.84,40.08,192.13,89.00,[],0,[],0,0.00,0.00,0.00,0.00
3,3,4,5.70,         0,284552.85,0.00,0.00,0.00,0.00,1.2,1.3,[],42.94,42.94,BB,Y,1,67.64,38.40,0.00,0.00,         0,         0,0,0,0,0,[],[],[],[],[],[],[],[],0,0,0,0,0,0,0,0,[],fix,fix,0.00,0.00,0.00,0.00,-43.25,52.84,0.00,0.00,0.00,139.58,139.29,0.00,0.00,36.71,40.08,0.00,48.92,0.00,0.00,0.00,0.00,52.84,40.08,192.13,89.00,[],0,[],0,0.00,0.00,0.00,0.00
4,4,5,5.64,         0,284552.85,0.00,0.00,0.00,0.00,1.2,1.3,[],41.71,41.71,BB,Y,1,65.69,37.71,0.00,0.00,         0,         0,0,0,0,0,[],[],[],[],[],[],[],[],0,0,0,0,0,0,0,0,[],fix,fix,0.00,0.00,0.00,0.00,-52.66,7.32,0.00,0.00,0.00,140.78,193.28,0.00,0.00,45.75,29.67,0.00,59.23,0.00,0.00,0.00,0.00,52.66,45.75,200.60,104.98,[],0,[],0,0.00,0.00,0.00,0.00
5,1,6,13.48,         0,284552.85,0.00,0.00,0.00,0.00,1.2,1.3,[],323.11,323.11,BB,X,1,493.26,127.16,0.00,0.00,         0,         0,0,0,0,0,[],[],[],[],[],[],[],[],0,0,0,0,0,0,0,0,[],fix,fix,0.00,-28.60,28.60,0.00,0.00,0.00,0.00,237.39,237.39,0.00,0.00,127.16,127.16,0.00,0.00,35.22,0.00,0.00,0.00,0.00,0.00,28.60,127.16,266.00,162.38,0,[],0,[],0.00,0.00,0.00,0.00
6,6,7,5.64,         0,284552.85,0.00,0.00,0.00,0.00,1.2,1.3,[],41.71,41.71,BB,Y,1,65.69,37.71,0.00,0.00,         0,         0,0,0,0,0,[],[],[],[],[],[],[],[],0,0,0,0,0,0,0,0,[],fix,fix,0.00,0.00,0.00,0.00,-7.32,52.66,0.00,0.00,0.00,193.28,140.78,0.00,0.00,29.67,45.75,0.00,59.23,0.00,0.00,0.00,0.00,52.66,45.75,200.60,104.98,[],0,[],0,0.00,0.00,0.00,0.00
7,7,8,5.70,         0,284552.85,0.00,0.00,0.00,0.00,1.2,1.3,[],42.94,42.94,BB,Y,1,67.64,38.40,0.00,0.00,         0,         0,0,0,0,0,[],[],[],[],[],[],[],[],0,0,0,0,0,0,0,0,[],fix,fix,0.00,0.00,0.00,0.00,-52.84,43.25,0.00,0.00,0.00,139.29,139.58,0.00,0.00,40.08,36.71,0.00,48.92,0.00,0.00,0.00,0.00,52.84,40.08,192.13,89.00,[],0,[],0,0.00,0.00,0.00,0.00
8,8,9,5.70,         0,284552.85,0.00,0.00,0.00,0.00,1.2,1.3,[],42.94,42.94,BB,Y,1,67.64,38.40,0.00,0.00,         0,         0,0,0,0,0,[],[],[],[],[],[],[],[],0,0,0,0,0,0,0,0,[],fix,fix,0.00,0.00,0.00,0.00,-43.25,52.84,0.00,0.00,0.00,139.58,139.29,0.00,0.00,36.71,40.08,0.00,48.92,0.00,0.00,0.00,0.00,52.84,40.08,192.13,89.00,[],0,[],0,0.00,0.00,0.00,0.00
9,9,10,5.64,         0,284552.85,0.00,0.00,0.00,0.00,1.2,1.3,[],41.71,41.71,BB,Y,1,65.69,37.71,0.00,0.00,         0,         0,0,0,0,0,[],[],[],[],[],[],[],[],0,0,0,0,0,0,0,0,[],fix,fix,0.00,0.00,0.00,0.00,-52.66,7.32,0.00,0.00,0.00,140.78,193.28,0.00,0.00,45.75,29.67,0.00,59.23,0.00,0.00,0.00,0.00,52.66,45.75,200.60,104.98,[],0,[],0,0.00,0.00,0.00,0.00
10,2,7,13.48,         0,284552.85,0.00,0.00,0.00,0.00,1.4,1.6,[],529.71,529.71,BB,X,1,811.98,202.19,0.00,0.00,         0,         0,0,0,0,0,[],[],[],[],[],[],[],[],0,0,0,0,0,0,0,0,[],fix,fix,0.00,-42.44,42.44,0.00,0.00,0.00,0.00,281.44,281.44,0.00,0.00,202.19,202.19,0.00,0.00,41.76,0.00,0.00,0.00,0.00,0.00,42.44,202.19,323.88,243.95,0,[],0,[],0.00,0.00,0.00,0.00
11,3,8,13.48,         0,284552.85,0.00,0.00,0.00,0.00,1.4,1.6,[],532.06,532.06,BB,X,1,815.74,202.98,0.00,0.00,         0,         0,0,0,0,0,[],[],[],[],[],[],[],[],0,0,0,0,0,0,0,0,[],fix,fix,0.00,-42.63,42.63,0.00,0.00,0.00,0.00,281.44,281.44,0.00,0.00,202.98,202.98,0.00,0.00,41.76,0.00,0.00,0.00,0.00,0.00,42.63,202.98,324.07,244.74,0,[],0,[],0.00,0.00,0.00,0.00
12,4,9,13.48,         0,284552.85,0.00,0.00,0.00,0.00,1.4,1.6,[],529.71,529.71,BB,X,1,811.98,202.19,0.00,0.00,         0,         0,0,0,0,0,[],[],[],[],[],[],[],[],0,0,0,0,0,0,0,0,[],fix,fix,0.00,-42.44,42.44,0.00,0.00,0.00,0.00,281.44,281.44,0.00,0.00,202.19,202.19,0.00,0.00,41.76,0.00,0.00,0.00,0.00,0.00,42.44,202.19,323.88,243.95,0,[],0,[],0.00,0.00,0.00,0.00
13,5,10,13.48,         0,284552.85,0.00,0.00,0.00,0.00,1.2,1.3,[],323.11,323.11,BB,X,1,493.26,127.16,0.00,0.00,         0,         0,0,0,0,0,[],[],[],[],[],[],[],[],0,0,0,0,0,0,0,0,[],fix,fix,0.00,-28.60,28.60,0.00,0.00,0.00,0.00,237.39,237.39,0.00,0.00,127.16,127.16,0.00,0.00,35.22,0.00,0.00,0.00,0.00,0.00,28.60,127.16,266.00,162.38,0,[],0,[],0.00,0.00,0.00,0.00
14,11,12,5.64,0.000755569,174.16,0.68,0.68,1.13,1.13,1.2,1.3,1.3,41.71,41.71,nan,Y,2,65.69,37.71,0.64,3.62,0.002518562,0.002903812,200.0,400.0,8.0,13.0,200.0,600.0,11.0,17.0,200.0,600.0,11.0,17.0,200.0,600.0,11.0,17.0,200.0,600.0,11.0,17.0,[],fix,fix,682.40,0.00,0.00,0.00,-32.61,46.29,26.24,0.00,0.00,341.27,285.68,0.00,0.00,35.28,40.14,0.00,111.16,0.00,0.00,0.00,0.00,46.29,40.14,373.88,151.30,[],6.82945109265734e-05,[],0.0003019926119307531,23.97,6.76,193.60,25.47
15,12,13,5.70,0.000755569,172.32,0.67,0.67,1.12,1.12,1.2,1.3,1.3,42.94,42.94,nan,Y,2,67.64,38.40,0.64,3.66,0.002518562,0.002903812,200.0,400.0,8.0,13.0,200.0,600.0,11.0,17.0,200.0,600.0,11.0,17.0,200.0,600.0,11.0,17.0,200.0,600.0,11.0,17.0,[],fix,fix,682.40,0.00,0.00,0.00,-43.87,43.07,24.17,0.00,0.00,282.67,283.29,0.00,0.00,38.54,38.26,0.00,99.29,0.00,0.00,0.00,0.00,43.87,38.54,326.54,137.83,[],-2.84353965601474e-06,[],0.0002601676933305135,22.71,6.49,169.08,23.20
16,13,14,5.70,0.000755569,172.32,0.67,0.67,1.12,1.12,1.2,1.3,1.3,42.94,42.94,nan,Y,2,67.64,38.40,0.64,3.66,0.002518562,0.002903812,200.0,400.0,8.0,13.0,200.0,600.0,11.0,17.0,200.0,600.0,11.0,17.0,200.0,600.0,11.0,17.0,200.0,600.0,11.0,17.0,[],fix,fix,682.40,0.00,0.00,0.00,-43.07,43.87,24.17,0.00,0.00,283.29,282.67,0.00,0.00,38.26,38.54,0.00,99.29,0.00,0.00,0.00,0.00,43.87,38.54,326.54,137.83,[],-2.84353965601474e-06,[],0.0002601676933305134,22.71,6.49,169.08,23.20
17,14,15,5.64,0.000755569,174.16,0.68,0.68,1.13,1.13,1.2,1.3,1.3,41.71,41.71,nan,Y,2,65.69,37.71,0.64,3.62,0.002518562,0.002903812,200.0,400.0,8.0,13.0,200.0,600.0,11.0,17.0,200.0,600.0,11.0,17.0,200.0,600.0,11.0,17.0,200.0,600.0,11.0,17.0,[],fix,fix,682.40,0.00,0.00,0.00,-46.29,32.61,26.24,0.00,0.00,285.68,341.27,0.00,0.00,40.14,35.28,0.00,111.16,0.00,0.00,0.00,0.00,46.29,40.14,373.88,151.30,[],6.82945109265734e-05,[],0.0003019926119307532,23.97,6.76,193.60,25.47
18,11,16,13.48,0.001143501,110.28,3.21,3.21,0.71,0.71,1.2,1.3,1.3,323.11,323.11,nan,X,2,493.26,127.16,2.03,27.34,0.00388946,0.00434824,300.0,800.0,14.0,26.0,300.0,588.0,12.0,20.0,300.0,588.0,12.0,20.0,300.0,588.0,12.0,20.0,300.0,588.0,12.0,20.0,[],fix,fix,1413.18,-176.80,176.80,316.46,0.00,0.00,0.00,379.53,379.53,0.00,0.00,127.16,127.16,0.00,0.00,56.31,0.00,0.00,0.00,0.00,0.00,316.46,127.16,556.33,183.47,0.01350651587971163,[],0.01745983567756934,[],96.22,20.30,169.16,29.29
19,16,17,5.64,0.000755569,174.16,0.68,0.68,1.13,1.13,1.2,1.3,1.3,41.71,41.71,nan,Y,2,65.69,37.71,0.64,3.62,0.002518562,0.002903812,200.0,400.0,8.0,13.0,200.0,600.0,11.0,17.0,200.0,600.0,11.0,17.0,200.0,600.0,11.0,17.0,200.0,600.0,11.0,17.0,[],fix,fix,682.40,0.00,0.00,0.00,-32.61,46.29,26.24,0.00,0.00,341.27,285.68,0.00,0.00,35.28,40.14,0.00,111.16,0.00,0.00,0.00,0.00,46.29,40.14,373.88,151.30,[],6.82945109265734e-05,[],0.0003019926119307531,23.97,6.76,193.60,25.47
20,17,18,5.70,0.000755569,172.32,0.67,0.67,1.12,1.12,1.2,1.3,1.3,42.94,42.94,nan,Y,2,67.64,38.40,0.64,3.66,0.002518562,0.002903812,200.0,400.0,8.0,13.0,200.0,600.0,11.0,17.0,200.0,600.0,11.0,17.0,200.0,600.0,11.0,17.0,200.0,600.0,11.0,17.0,[],fix,fix,682.40,0.00,0.00,0.00,-43.87,43.07,24.17,0.00,0.00,282.67,283.29,0.00,0.00,38.54,38.26,0.00,99.29,0.00,0.00,0.00,0.00,43.87,38.54,326.54,137.83,[],-2.84353965601474e-06,[],0.0002601676933305135,22.71,6.49,169.08,23.20
21,18,19,5.70,0.000755569,172.32,0.67,0.67,1.12,1.12,1.2,1.3,1.3,42.94,42.94,nan,Y,2,67.64,38.40,0.64,3.66,0.002518562,0.002903812,200.0,400.0,8.0,13.0,200.0,600.0,11.0,17.0,200.0,600.0,11.0,17.0,200.0,600.0,11.0,17.0,200.0,600.0,11.0,17.0,[],fix,fix,682.40,0.00,0.00,0.00,-43.07,43.87,24.17,0.00,0.00,283.29,282.67,0.00,0.00,38.26,38.54,0.00,99.29,0.00,0.00,0.00,0.00,43.87,38.54,326.54,137.83,[],-2.84353965601474e-06,[],0.0002601676933305134,22.71,6.49,169.08,23.20
22,19,20,5.64,0.000755569,174.16,0.68,0.68,1.13,1.13,1.2,1.3,1.3,41.71,41.71,nan,Y,2,65.69,37.71,0.64,3.62,0.002518562,0.002903812,200.0,400.0,8.0,13.0,200.0,600.0,11.0,17.0,200.0,600.0,11.0,17.0,200.0,600.0,11.0,17.0,200.0,600.0,11.0,17.0,[],fix,fix,682.40,0.00,0.00,0.00,-46.29,32.61,26.24,0.00,0.00,285.68,341.27,0.00,0.00,40.14,35.28,0.00,111.16,0.00,0.00,0.00,0.00,46.29,40.14,373.88,151.30,[],6.82945109265734e-05,[],0.0003019926119307532,23.97,6.76,193.60,25.47
23,12,17,13.48,0.001143501,135.73,3.74,3.74,0.88,0.88,1.4,1.6,1.6,529.71,529.71,nan,X,2,811.98,202.19,2.03,27.34,0.00388946,0.00434824,300.0,800.0,14.0,26.0,300.0,588.0,12.0,20.0,300.0,588.0,12.0,20.0,300.0,588.0,12.0,20.0,300.0,588.0,12.0,20.0,[],fix,fix,1413.18,-267.48,267.48,544.50,0.00,0.00,0.00,446.27,446.27,0.00,0.00,202.19,202.19,0.00,0.00,66.21,0.00,0.00,0.00,0.00,0.00,544.50,202.19,713.75,268.41,0.01505998197118786,[],0.024779030513101496,[],165.56,32.28,217.02,42.85
24,13,18,13.48,0.001143501,135.73,3.74,3.74,0.88,0.88,1.4,1.6,1.6,532.06,532.06,nan,X,2,815.74,202.98,2.03,27.34,0.00388946,0.00434824,300.0,800.0,14.0,26.0,300.0,588.0,12.0,20.0,300.0,588.0,12.0,20.0,300.0,588.0,12.0,20.0,300.0,588.0,12.0,20.0,[],fix,fix,1413.18,-268.67,268.67,547.07,0.00,0.00,0.00,446.27,446.27,0.00,0.00,202.98,202.98,0.00,0.00,66.21,0.00,0.00,0.00,0.00,0.00,547.07,202.98,714.94,269.19,0.015134680323365356,[],0.024896830872673175,[],166.34,32.40,217.38,42.97
25,14,19,13.48,0.001143501,135.73,3.74,3.74,0.88,0.88,1.4,1.6,1.6,529.71,529.71,nan,X,2,811.98,202.19,2.03,27.34,0.00388946,0.00434824,300.0,800.0,14.0,26.0,300.0,588.0,12.0,20.0,300.0,588.0,12.0,20.0,300.0,588.0,12.0,20.0,300.0,588.0,12.0,20.0,[],fix,fix,1413.18,-267.48,267.48,544.50,0.00,0.00,0.00,446.27,446.27,0.00,0.00,202.19,202.19,0.00,0.00,66.21,0.00,0.00,0.00,0.00,0.00,544.50,202.19,713.75,268.41,0.01505998197118786,[],0.024779030513101496,[],165.56,32.28,217.02,42.85
26,15,20,13.48,0.001143501,110.28,3.21,3.21,0.71,0.71,1.2,1.3,1.3,323.11,323.11,nan,X,2,493.26,127.16,2.03,27.34,0.00388946,0.00434824,300.0,800.0,14.0,26.0,300.0,588.0,12.0,20.0,300.0,588.0,12.0,20.0,300.0,588.0,12.0,20.0,300.0,588.0,12.0,20.0,[],fix,fix,1413.18,-176.80,176.80,316.46,0.00,0.00,0.00,379.53,379.53,0.00,0.00,127.16,127.16,0.00,0.00,56.31,0.00,0.00,0.00,0.00,0.00,316.46,127.16,556.33,183.47,0.01350651587971163,[],0.01745983567756934,[],96.22,20.30,169.16,29.29
27,21,22,5.64,0.000408344,94.12,0.68,0.68,0.61,0.61,1.2,1.3,1.3,41.64,41.64,nan,Y,3,65.64,37.54,0.64,3.62,0.001646549,0.001869181,200.0,400.0,8.0,13.0,199.0,496.0,9.0,14.0,199.0,496.0,9.0,14.0,199.0,496.0,9.0,14.0,199.0,496.0,9.0,14.0,[],fix,fix,439.26,0.00,0.00,0.00,-36.05,46.03,24.60,0.00,0.00,220.23,173.68,0.00,0.00,35.77,39.31,0.00,69.84,0.00,0.00,0.00,0.00,46.03,39.31,256.29,109.16,[],4.9168523624759696e-05,[],0.0004990656694103756,34.93,9.88,194.45,27.44
28,22,23,5.70,0.000408344,93.13,0.67,0.67,0.60,0.60,1.2,1.3,1.3,42.88,42.88,nan,Y,3,67.60,38.23,0.64,3.66,0.001646549,0.001869181,200.0,400.0,8.0,13.0,199.0,496.0,9.0,14.0,199.0,496.0,9.0,14.0,199.0,496.0,9.0,14.0,199.0,496.0,9.0,14.0,[],fix,fix,439.26,0.00,0.00,0.00,-43.79,43.00,24.20,0.00,0.00,171.86,172.24,0.00,0.00,38.37,38.09,0.00,60.37,0.00,0.00,0.00,0.00,43.79,38.37,215.65,98.74,[],-3.1970117932550966e-06,[],0.0007005953453548953,33.23,9.65,163.62,24.82
29,23,24,5.70,0.000408344,93.13,0.67,0.67,0.60,0.60,1.2,1.3,1.3,42.88,42.88,nan,Y,3,67.60,38.23,0.64,3.66,0.001646549,0.001869181,200.0,400.0,8.0,13.0,199.0,496.0,9.0,14.0,199.0,496.0,9.0,14.0,199.0,496.0,9.0,14.0,199.0,496.0,9.0,14.0,[],fix,fix,439.26,0.00,0.00,0.00,-43.00,43.79,24.20,0.00,0.00,172.24,171.86,0.00,0.00,38.09,38.37,0.00,60.37,0.00,0.00,0.00,0.00,43.79,38.37,215.65,98.74,[],-3.197011793254663e-06,[],0.0007005953453548949,33.23,9.65,163.62,24.82
30,24,25,5.64,0.000408344,94.12,0.68,0.68,0.61,0.61,1.2,1.3,1.3,41.64,41.64,nan,Y,3,65.64,37.54,0.64,3.62,0.001646549,0.001869181,200.0,400.0,8.0,13.0,199.0,496.0,9.0,14.0,199.0,496.0,9.0,14.0,199.0,496.0,9.0,14.0,199.0,496.0,9.0,14.0,[],fix,fix,439.26,0.00,0.00,0.00,-46.03,36.05,24.60,0.00,0.00,173.68,220.23,0.00,0.00,39.31,35.77,0.00,69.84,0.00,0.00,0.00,0.00,46.03,39.31,256.29,109.16,[],4.916852362475991e-05,[],0.000499065669410376,34.93,9.88,194.45,27.44
31,21,26,13.48,0.001143501,110.28,3.21,3.21,0.71,0.71,1.2,1.3,1.3,324.02,324.02,nan,X,3,494.75,127.31,2.03,27.34,0.00388946,0.00434824,300.0,800.0,14.0,26.0,300.0,588.0,12.0,20.0,300.0,588.0,12.0,20.0,300.0,588.0,12.0,20.0,300.0,588.0,12.0,20.0,[],fix,fix,1413.18,-205.64,205.64,289.11,0.00,0.00,0.00,283.40,283.40,0.00,0.00,127.31,127.31,0.00,0.00,42.05,0.00,0.00,0.00,0.00,0.00,289.11,127.31,489.04,169.36,0.010804767373076323,[],0.02557859203575548,[],87.91,20.32,148.70,27.04
32,26,27,5.64,0.000408344,94.12,0.68,0.68,0.61,0.61,1.2,1.3,1.3,41.64,41.64,nan,Y,3,65.64,37.54,0.64,3.62,0.001646549,0.001869181,200.0,400.0,8.0,13.0,199.0,496.0,9.0,14.0,199.0,496.0,9.0,14.0,199.0,496.0,9.0,14.0,199.0,496.0,9.0,14.0,[],fix,fix,439.26,0.00,0.00,0.00,-36.05,46.03,24.60,0.00,0.00,220.23,173.68,0.00,0.00,35.77,39.31,0.00,69.84,0.00,0.00,0.00,0.00,46.03,39.31,256.29,109.16,[],4.9168523624759696e-05,[],0.0004990656694103756,34.93,9.88,194.45,27.44
33,27,28,5.70,0.000408344,93.13,0.67,0.67,0.60,0.60,1.2,1.3,1.3,42.88,42.88,nan,Y,3,67.60,38.23,0.64,3.66,0.001646549,0.001869181,200.0,400.0,8.0,13.0,199.0,496.0,9.0,14.0,199.0,496.0,9.0,14.0,199.0,496.0,9.0,14.0,199.0,496.0,9.0,14.0,[],fix,fix,439.26,0.00,0.00,0.00,-43.79,43.00,24.20,0.00,0.00,171.86,172.24,0.00,0.00,38.37,38.09,0.00,60.37,0.00,0.00,0.00,0.00,43.79,38.37,215.65,98.74,[],-3.1970117932550966e-06,[],0.0007005953453548953,33.23,9.65,163.62,24.82
34,28,29,5.70,0.000408344,93.13,0.67,0.67,0.60,0.60,1.2,1.3,1.3,42.88,42.88,nan,Y,3,67.60,38.23,0.64,3.66,0.001646549,0.001869181,200.0,400.0,8.0,13.0,199.0,496.0,9.0,14.0,199.0,496.0,9.0,14.0,199.0,496.0,9.0,14.0,199.0,496.0,9.0,14.0,[],fix,fix,439.26,0.00,0.00,0.00,-43.00,43.79,24.20,0.00,0.00,172.24,171.86,0.00,0.00,38.09,38.37,0.00,60.37,0.00,0.00,0.00,0.00,43.79,38.37,215.65,98.74,[],-3.197011793254663e-06,[],0.0007005953453548949,33.23,9.65,163.62,24.82
35,29,30,5.64,0.000408344,94.12,0.68,0.68,0.61,0.61,1.2,1.3,1.3,41.64,41.64,nan,Y,3,65.64,37.54,0.64,3.62,0.001646549,0.001869181,200.0,400.0,8.0,13.0,199.0,496.0,9.0,14.0,199.0,496.0,9.0,14.0,199.0,496.0,9.0,14.0,199.0,496.0,9.0,14.0,[],fix,fix,439.26,0.00,0.00,0.00,-46.03,36.05,24.60,0.00,0.00,173.68,220.23,0.00,0.00,39.31,35.77,0.00,69.84,0.00,0.00,0.00,0.00,46.03,39.31,256.29,109.16,[],4.916852362475991e-05,[],0.000499065669410376,34.93,9.88,194.45,27.44
36,22,27,13.48,0.001143501,135.73,3.74,3.74,0.88,0.88,1.4,1.6,1.6,537.62,537.62,nan,X,3,824.10,205.21,2.03,27.34,0.00388946,0.00434824,300.0,800.0,14.0,26.0,300.0,588.0,12.0,20.0,300.0,588.0,12.0,20.0,300.0,588.0,12.0,20.0,300.0,588.0,12.0,20.0,[],fix,fix,1413.18,-319.26,319.26,504.84,0.00,0.00,0.00,326.09,326.09,0.00,0.00,205.21,205.21,0.00,0.00,48.38,0.00,0.00,0.00,0.00,0.00,504.84,205.21,645.36,253.59,0.010654049460099995,[],0.02225467406257852,[],153.50,32.76,196.23,40.48
37,23,28,13.48,0.001143501,135.73,3.74,3.74,0.88,0.88,1.4,1.6,1.6,540.00,540.00,nan,X,3,827.92,206.01,2.03,27.34,0.00388946,0.00434824,300.0,800.0,14.0,26.0,300.0,588.0,12.0,20.0,300.0,588.0,12.0,20.0,300.0,588.0,12.0,20.0,300.0,588.0,12.0,20.0,[],fix,fix,1413.18,-320.68,320.68,507.24,0.00,0.00,0.00,326.09,326.09,0.00,0.00,206.01,206.01,0.00,0.00,48.38,0.00,0.00,0.00,0.00,0.00,507.24,206.01,646.77,254.39,0.010709326465351287,[],0.02236139748261692,[],154.23,32.89,196.66,40.61
38,24,29,13.48,0.001143501,135.73,3.74,3.74,0.88,0.88,1.4,1.6,1.6,537.62,537.62,nan,X,3,824.10,205.21,2.03,27.34,0.00388946,0.00434824,300.0,800.0,14.0,26.0,300.0,588.0,12.0,20.0,300.0,588.0,12.0,20.0,300.0,588.0,12.0,20.0,300.0,588.0,12.0,20.0,[],fix,fix,1413.18,-319.26,319.26,504.84,0.00,0.00,0.00,326.09,326.09,0.00,0.00,205.21,205.21,0.00,0.00,48.38,0.00,0.00,0.00,0.00,0.00,504.84,205.21,645.36,253.59,0.010654049460099995,[],0.02225467406257852,[],153.50,32.76,196.23,40.48
39,25,30,13.48,0.001143501,110.28,3.21,3.21,0.71,0.71,1.2,1.3,1.3,324.02,324.02,nan,X,3,494.75,127.31,2.03,27.34,0.00388946,0.00434824,300.0,800.0,14.0,26.0,300.0,588.0,12.0,20.0,300.0,588.0,12.0,20.0,300.0,588.0,12.0,20.0,300.0,588.0,12.0,20.0,[],fix,fix,1413.18,-205.64,205.64,289.11,0.00,0.00,0.00,283.40,283.40,0.00,0.00,127.31,127.31,0.00,0.00,42.05,0.00,0.00,0.00,0.00,0.00,289.11,127.31,489.04,169.36,0.010804767373076323,[],0.02557859203575548,[],87.91,20.32,148.70,27.04
40,31,32,5.64,0.000281338,64.85,0.68,0.68,0.42,0.42,1.2,1.3,1.3,40.65,40.65,nan,Y,4,64.54,35.63,0.64,3.62,0.001261607,0.001422748,200.0,400.0,8.0,13.0,199.0,446.0,8.0,12.0,199.0,446.0,8.0,12.0,199.0,446.0,8.0,12.0,199.0,446.0,8.0,12.0,[],fix,fix,334.35,0.00,0.00,0.00,-27.24,46.81,27.52,0.00,0.00,108.36,90.10,0.00,0.00,32.17,39.10,0.00,35.19,0.00,0.00,0.00,0.00,46.81,39.10,136.91,74.29,[],0.00029991000383156963,[],0.0008889328084512003,45.70,12.34,133.68,23.45
41,32,33,5.70,0.000281338,64.16,0.67,0.67,0.42,0.42,1.2,1.3,1.3,41.90,41.90,nan,Y,4,66.54,36.34,0.64,3.66,0.001261607,0.001422748,200.0,400.0,8.0,13.0,199.0,446.0,8.0,12.0,199.0,446.0,8.0,12.0,199.0,446.0,8.0,12.0,199.0,446.0,8.0,12.0,[],fix,fix,334.35,0.00,0.00,0.00,-43.95,42.08,23.53,0.00,0.00,89.15,89.31,0.00,0.00,36.67,36.01,0.00,31.31,0.00,0.00,0.00,0.00,43.95,36.67,133.10,67.98,[],-2.5356479408292828e-05,[],0.0006736605200262009,42.91,11.57,129.96,21.46
42,33,34,5.70,0.000281338,64.16,0.67,0.67,0.42,0.42,1.2,1.3,1.3,41.90,41.90,nan,Y,4,66.54,36.34,0.64,3.66,0.001261607,0.001422748,200.0,400.0,8.0,13.0,199.0,446.0,8.0,12.0,199.0,446.0,8.0,12.0,199.0,446.0,8.0,12.0,199.0,446.0,8.0,12.0,[],fix,fix,334.35,0.00,0.00,0.00,-42.08,43.95,23.53,0.00,0.00,89.31,89.15,0.00,0.00,36.01,36.67,0.00,31.31,0.00,0.00,0.00,0.00,43.95,36.67,133.10,67.98,[],-2.5356479408292828e-05,[],0.0006736605200262009,42.91,11.57,129.96,21.46
43,34,35,5.64,0.000281338,64.85,0.68,0.68,0.42,0.42,1.2,1.3,1.3,40.65,40.65,nan,Y,4,64.54,35.63,0.64,3.62,0.001261607,0.001422748,200.0,400.0,8.0,13.0,199.0,446.0,8.0,12.0,199.0,446.0,8.0,12.0,199.0,446.0,8.0,12.0,199.0,446.0,8.0,12.0,[],fix,fix,334.35,0.00,0.00,0.00,-46.81,27.24,27.52,0.00,0.00,90.10,108.36,0.00,0.00,39.10,32.17,0.00,35.19,0.00,0.00,0.00,0.00,46.81,39.10,136.91,74.29,[],0.0002999100038315705,[],0.0008889328084512016,45.70,12.34,133.68,23.45
44,31,36,13.48,0.001974907,175.81,3.21,3.21,1.14,1.14,1.2,1.3,1.3,329.08,329.08,nan,X,4,503.43,127.45,2.03,27.34,0.00564259,0.006338338,300.0,800.0,14.0,26.0,300.0,700.0,13.0,24.0,300.0,700.0,13.0,24.0,300.0,700.0,13.0,24.0,300.0,700.0,13.0,24.0,[],fix,fix,2059.96,-131.78,131.78,371.65,0.00,0.00,0.00,163.79,163.79,0.00,0.00,127.45,127.45,0.00,0.00,24.30,0.00,0.00,0.00,0.00,0.00,371.65,127.45,371.65,151.75,0.010711728928541785,[],0.021446658746441687,[],78.71,15.92,78.71,18.95
45,36,37,5.64,0.000281338,64.85,0.68,0.68,0.42,0.42,1.2,1.3,1.3,40.65,40.65,nan,Y,4,64.54,35.63,0.64,3.62,0.001261607,0.001422748,200.0,400.0,8.0,13.0,199.0,446.0,8.0,12.0,199.0,446.0,8.0,12.0,199.0,446.0,8.0,12.0,199.0,446.0,8.0,12.0,[],fix,fix,334.35,0.00,0.00,0.00,-27.24,46.81,27.52,0.00,0.00,108.36,90.10,0.00,0.00,32.17,39.10,0.00,35.19,0.00,0.00,0.00,0.00,46.81,39.10,136.91,74.29,[],0.00029991000383156963,[],0.0008889328084512003,45.70,12.34,133.68,23.45
46,37,38,5.70,0.000281338,64.16,0.67,0.67,0.42,0.42,1.2,1.3,1.3,41.90,41.90,nan,Y,4,66.54,36.34,0.64,3.66,0.001261607,0.001422748,200.0,400.0,8.0,13.0,199.0,446.0,8.0,12.0,199.0,446.0,8.0,12.0,199.0,446.0,8.0,12.0,199.0,446.0,8.0,12.0,[],fix,fix,334.35,0.00,0.00,0.00,-43.95,42.08,23.53,0.00,0.00,89.15,89.31,0.00,0.00,36.67,36.01,0.00,31.31,0.00,0.00,0.00,0.00,43.95,36.67,133.10,67.98,[],-2.5356479408292828e-05,[],0.0006736605200262009,42.91,11.57,129.96,21.46
47,38,39,5.70,0.000281338,64.16,0.67,0.67,0.42,0.42,1.2,1.3,1.3,41.90,41.90,nan,Y,4,66.54,36.34,0.64,3.66,0.001261607,0.001422748,200.0,400.0,8.0,13.0,199.0,446.0,8.0,12.0,199.0,446.0,8.0,12.0,199.0,446.0,8.0,12.0,199.0,446.0,8.0,12.0,[],fix,fix,334.35,0.00,0.00,0.00,-42.08,43.95,23.53,0.00,0.00,89.31,89.15,0.00,0.00,36.01,36.67,0.00,31.31,0.00,0.00,0.00,0.00,43.95,36.67,133.10,67.98,[],-2.5356479408292828e-05,[],0.0006736605200262009,42.91,11.57,129.96,21.46
48,39,40,5.64,0.000281338,64.85,0.68,0.68,0.42,0.42,1.2,1.3,1.3,40.65,40.65,nan,Y,4,64.54,35.63,0.64,3.62,0.001261607,0.001422748,200.0,400.0,8.0,13.0,199.0,446.0,8.0,12.0,199.0,446.0,8.0,12.0,199.0,446.0,8.0,12.0,199.0,446.0,8.0,12.0,[],fix,fix,334.35,0.00,0.00,0.00,-46.81,27.24,27.52,0.00,0.00,90.10,108.36,0.00,0.00,39.10,32.17,0.00,35.19,0.00,0.00,0.00,0.00,46.81,39.10,136.91,74.29,[],0.0002999100038315705,[],0.0008889328084512016,45.70,12.34,133.68,23.45
49,32,37,13.48,0.001974907,205.11,3.74,3.74,1.33,1.33,1.4,1.6,1.4,604.82,604.82,nan,X,4,927.11,230.86,2.03,27.34,0.00564259,0.006338338,300.0,800.0,14.0,26.0,300.0,700.0,13.0,24.0,300.0,700.0,13.0,24.0,300.0,700.0,13.0,24.0,300.0,700.0,13.0,24.0,[],fix,fix,2059.96,-214.86,214.86,712.25,0.00,0.00,0.00,183.98,183.98,0.00,0.00,230.86,230.86,0.00,0.00,27.30,0.00,0.00,0.00,0.00,0.00,712.25,230.86,712.25,258.16,0.01890636855304187,[],0.02235051582637941,[],150.85,28.83,150.85,32.24
50,33,38,13.48,0.001974907,205.11,3.74,3.74,1.33,1.33,1.4,1.6,1.4,607.50,607.50,nan,X,4,931.40,231.76,2.03,27.34,0.00564259,0.006338338,300.0,800.0,14.0,26.0,300.0,700.0,13.0,24.0,300.0,700.0,13.0,24.0,300.0,700.0,13.0,24.0,300.0,700.0,13.0,24.0,[],fix,fix,2059.96,-215.82,215.82,715.59,0.00,0.00,0.00,183.98,183.98,0.00,0.00,231.76,231.76,0.00,0.00,27.30,0.00,0.00,0.00,0.00,0.00,715.59,231.76,715.59,259.06,0.018996191232642783,[],0.022455612599597406,[],151.56,28.94,151.56,32.35
51,34,39,13.48,0.001974907,205.11,3.74,3.74,1.33,1.33,1.4,1.6,1.4,604.82,604.82,nan,X,4,927.11,230.86,2.03,27.34,0.00564259,0.006338338,300.0,800.0,14.0,26.0,300.0,700.0,13.0,24.0,300.0,700.0,13.0,24.0,300.0,700.0,13.0,24.0,300.0,700.0,13.0,24.0,[],fix,fix,2059.96,-214.86,214.86,712.25,0.00,0.00,0.00,183.98,183.98,0.00,0.00,230.86,230.86,0.00,0.00,27.30,0.00,0.00,0.00,0.00,0.00,712.25,230.86,712.25,258.16,0.01890636855304187,[],0.02235051582637941,[],150.85,28.83,150.85,32.24
52,35,40,13.48,0.001974907,175.81,3.21,3.21,1.14,1.14,1.2,1.3,1.3,329.08,329.08,nan,X,4,503.43,127.45,2.03,27.34,0.00564259,0.006338338,300.0,800.0,14.0,26.0,300.0,700.0,13.0,24.0,300.0,700.0,13.0,24.0,300.0,700.0,13.0,24.0,300.0,700.0,13.0,24.0,[],fix,fix,2059.96,-131.78,131.78,371.65,0.00,0.00,0.00,163.79,163.79,0.00,0.00,127.45,127.45,0.00,0.00,24.30,0.00,0.00,0.00,0.00,0.00,371.65,127.45,371.65,151.75,0.010711728928541785,[],0.021446658746441687,[],78.71,15.92,78.71,18.95
<column_data>
No,i,j,story,length(m),A(m2),Ix(m4),Iy(m4),Z(m3),Zp(m3),initial_H(mm),initial_t(mm),initial_stiff_ratio_x,initial_stiff_ratio_y,initial_base_K,H(mm),t(mm),stiff_ratio_x,stiff_ratio_y,F(N/mm2),base_K(cm3),load_area(m2),init_group,Mpx(kNm),Mpy(kNm),unit_weight(kg/m),weight(kg),y0_x,y1_x,y2_x,y3_x,y0_y,y1_y,y2_y,y3_y,k,a,D_x,D_y,M_Lx_i(kNm),M_Lx_j(kNm),M_Ly_i(kNm),M_Ly_j(kNm),M_Sx_i(kNm),M_Sx_j(kNm),M_Sy_i(kNm),M_Sy_j(kNm),Q_Lx_i(kN),Q_Lx_j(kN),Q_Ly_i(kN),Q_Ly_j(kN),Q_Sx(kN),Q_Sy(kN),N_Lx(kN),N_Ly(kN),N_Sx(kN),N_Sy(kN),MLx(kNm),MLy(kNm),QLx(kN),QLy(kN),NL(kN),MSx(kNm),MSy(kNm),QSx(kN),QSy(kN),NSx(kN),NSy(kN),required_area(m2),decrement_ratio_x,decrement_ratio_y,minimum_selected_section_no,tc1(mm),tc2x(mm),tc2y(mm),tc(mm)
1,1,11,1,4.1,0.0237,0.000571,0.000571,[],0.00337,350.0,12.0,0.90,0.90,170731.7073,400.0,16.0,0.90,0.90,295.0,284552.8455,19.01,[],979.90,986.92,1.82,7.48,0.75,-0.25,0.0,0,0.7,-0.2,0.0,0,0.63,0.24,0.15,0.21,34.88,69.76,5.95,11.90,237.39,237.39,193.28,193.28,25.52,25.52,4.35,4.35,115.80,94.28,492.81,492.81,122.66,216.19,69.76,11.90,25.52,4.35,492.81,307.15,205.18,141.32,98.64,615.47,709.01,4176.39,0.99,0.99,13.00,4.06,6.64,4.86,6.64
2,11,21,2,3.75,0.0237,0.000571,0.000571,[],0.00337,350.0,12.0,0.99,0.99,170731.7073,400.0,16.0,0.99,0.99,295.0,284552.8455,19.01,[],986.95,992.11,1.82,6.84,0.4,-0.0,0.0,0.0,0.4,0.1,0.0,0.0,0.88,0.31,0.26,0.30,107.04,98.45,20.71,15.93,142.14,213.21,147.99,147.99,54.80,54.80,9.77,9.77,94.76,78.93,327.95,327.95,66.35,105.03,107.04,20.71,54.80,9.77,327.95,320.25,168.70,149.56,88.70,394.29,432.98,2779.20,0.99,1.00,13.00,4.62,6.45,3.80,6.45
3,21,31,3,3.700000000000001,0.0237,0.000571,0.000571,[],0.00337,350.0,12.0,1.00,1.00,170731.7073,400.0,16.0,1.00,1.00,295.0,284552.8455,19.01,[],991.62,993.77,1.82,6.75,0.35,-0.05,0,0.0,0.3,0.1,0,0.0,0.52,0.20,0.32,0.20,107.19,131.78,20.12,27.24,70.19,163.79,72.24,108.36,64.59,64.59,12.80,12.80,63.24,48.81,163.09,163.09,24.30,35.19,131.78,27.24,64.59,12.80,163.09,295.57,135.60,127.82,61.61,187.39,198.28,1382.10,1.00,1.00,13.00,4.80,5.59,2.79,5.59
4,2,12,1,4.1,0.0237,0.000571,0.000571,[],0.00337,350.0,12.0,0.90,0.90,170731.7073,400.0,16.0,0.90,0.90,295.0,284552.8455,38.22,[],979.90,994.15,1.82,7.48,0.7,-0.2,0.0,0,0.6,-0.15,0.0,0,1.24,0.38,0.18,0.35,52.83,105.66,-0.62,-1.24,281.44,281.44,280.07,342.31,38.66,38.66,-0.46,-0.46,137.29,151.80,862.13,862.13,141.89,25.22,105.66,1.24,38.66,-0.46,862.13,387.11,343.55,175.95,152.26,1004.02,887.35,7306.18,0.99,1.00,13.00,6.15,9.00,8.24,9.00
5,12,22,2,3.75,0.0237,0.000571,0.000571,[],0.00337,350.0,12.0,0.99,0.99,170731.7073,400.0,16.0,0.99,0.99,295.0,284552.8455,38.22,[],986.95,994.15,1.82,6.84,0.4,-0.0,0.0,0.0,0.45,0.05,0.0,0.0,1.75,0.47,0.30,0.46,161.82,150.25,-1.18,-1.15,164.83,247.24,226.04,226.04,83.22,83.22,-0.62,-0.62,109.89,120.55,583.83,583.83,75.68,13.35,161.82,1.18,83.22,-0.62,583.83,409.06,227.21,193.10,121.17,659.51,597.18,4947.70,0.99,1.00,13.00,6.54,8.66,5.48,8.66
6,22,32,3,3.700000000000001,0.0237,0.000571,0.000571,[],0.00337,350.0,12.0,1.00,1.00,170731.7073,400.0,16.0,1.00,1.00,295.0,284552.8455,38.22,[],991.62,994.15,1.82,6.75,0.35,-0.05,0,0.0,0.35,0.05,0,0.0,1.02,0.34,0.36,0.34,169.01,214.86,-1.09,-2.86,78.85,183.98,119.50,179.26,103.75,103.75,-1.07,-1.07,71.03,80.75,302.84,302.84,27.30,3.88,214.86,2.86,103.75,-1.07,302.84,398.84,182.11,174.79,81.81,330.14,306.72,2566.44,1.00,1.00,13.00,6.88,7.76,3.97,7.76
7,3,13,1,4.1,0.0237,0.000571,0.000571,[],0.00337,350.0,12.0,0.90,0.90,170731.7073,400.0,16.0,0.90,0.90,295.0,284552.8455,38.42,[],979.90,994.15,1.82,7.48,0.7,-0.2,0.0,0,0.6,-0.15,0.0,0,1.24,0.38,0.18,0.34,53.07,106.13,0.00,0.00,281.44,281.44,279.16,341.19,38.83,38.83,0.00,0.00,137.29,151.30,866.69,866.69,141.89,-0.00,106.13,0.00,38.83,0.00,866.69,387.58,341.19,176.12,151.30,1008.58,866.69,7344.84,0.99,1.00,13.00,6.15,9.02,8.21,9.02
8,13,23,2,3.75,0.0237,0.000571,0.000571,[],0.00337,350.0,12.0,0.99,0.99,170731.7073,400.0,16.0,0.99,0.99,295.0,284552.8455,38.42,[],986.95,994.15,1.82,6.84,0.4,-0.0,0.0,0.0,0.45,0.05,0.0,0.0,1.74,0.47,0.30,0.46,162.53,150.92,0.00,0.00,164.83,247.24,225.40,225.40,83.59,83.59,0.00,0.00,109.89,120.21,586.92,586.92,75.68,-0.00,162.53,0.00,83.59,0.00,586.92,409.78,225.40,193.47,120.21,662.60,586.92,4973.88,0.99,1.00,13.00,6.54,8.68,5.46,8.68
9,23,33,3,3.700000000000001,0.0237,0.000571,0.000571,[],0.00337,350.0,12.0,1.00,1.00,170731.7073,400.0,16.0,1.00,1.00,295.0,284552.8455,38.42,[],991.62,994.15,1.82,6.75,0.35,-0.05,0,0.0,0.35,0.05,0,0.0,1.02,0.34,0.36,0.34,169.76,215.82,0.00,0.00,78.85,183.98,119.09,178.63,104.21,104.21,0.00,0.00,71.03,80.46,304.44,304.44,27.30,-0.00,215.82,0.00,104.21,0.00,304.44,399.79,178.63,175.25,80.46,331.74,304.44,2580.02,1.00,1.00,13.00,6.84,7.78,3.91,7.78
10,4,14,1,4.1,0.0237,0.000571,0.000571,[],0.00337,350.0,12.0,0.90,0.90,170731.7073,400.0,16.0,0.90,0.90,295.0,284552.8455,38.22,[],979.90,994.15,1.82,7.48,0.7,-0.2,0.0,0,0.6,-0.15,0.0,0,1.24,0.38,0.18,0.35,52.83,105.66,0.62,1.24,281.44,281.44,280.07,342.31,38.66,38.66,0.46,0.46,137.29,151.80,862.13,862.13,141.89,-25.22,105.66,1.24,38.66,0.46,862.13,387.11,343.55,175.95,152.26,1004.02,887.35,7306.18,0.99,1.00,13.00,6.15,9.00,8.24,9.00
11,14,24,2,3.75,0.0237,0.000571,0.000571,[],0.00337,350.0,12.0,0.99,0.99,170731.7073,400.0,16.0,0.99,0.99,295.0,284552.8455,38.22,[],986.95,994.15,1.82,6.84,0.4,-0.0,0.0,0.0,0.45,0.05,0.0,0.0,1.75,0.47,0.30,0.46,161.82,150.25,1.18,1.15,164.83,247.24,226.04,226.04,83.22,83.22,0.62,0.62,109.89,120.55,583.83,583.83,75.68,-13.35,161.82,1.18,83.22,0.62,583.83,409.06,227.21,193.10,121.17,659.51,597.18,4947.70,0.99,1.00,13.00,6.54,8.66,5.48,8.66
12,24,34,3,3.700000000000001,0.0237,0.000571,0.000571,[],0.00337,350.0,12.0,1.00,1.00,170731.7073,400.0,16.0,1.00,1.00,295.0,284552.8455,38.22,[],991.62,994.15,1.82,6.75,0.35,-0.05,0,0.0,0.35,0.05,0,0.0,1.02,0.34,0.36,0.34,169.01,214.86,1.09,2.86,78.85,183.98,119.50,179.26,103.75,103.75,1.07,1.07,71.03,80.75,302.84,302.84,27.30,-3.88,214.86,2.86,103.75,1.07,302.84,398.84,182.11,174.79,81.81,330.14,306.72,2566.44,1.00,1.00,13.00,6.88,7.76,3.97,7.76
13,5,15,1,4.1,0.0237,0.000571,0.000571,[],0.00337,350.0,12.0,0.90,0.90,170731.7073,400.0,16.0,0.90,0.90,295.0,284552.8455,19.01,[],979.90,986.92,1.82,7.48,0.75,-0.25,0.0,0,0.7,-0.2,0.0,0,0.63,0.24,0.15,0.21,34.88,69.76,-5.95,-11.90,237.39,237.39,193.28,193.28,25.52,25.52,-4.35,-4.35,115.80,94.28,492.81,492.81,122.66,216.19,69.76,11.90,25.52,-4.35,492.81,307.15,205.18,141.32,98.64,615.47,709.01,4176.39,0.99,0.99,13.00,4.06,6.64,4.86,6.64
14,15,25,2,3.75,0.0237,0.000571,0.000571,[],0.00337,350.0,12.0,0.99,0.99,170731.7073,400.0,16.0,0.99,0.99,295.0,284552.8455,19.01,[],986.95,992.11,1.82,6.84,0.4,-0.0,0.0,0.0,0.4,0.1,0.0,0.0,0.88,0.31,0.26,0.30,107.04,98.45,-20.71,-15.93,142.14,213.21,147.99,147.99,54.80,54.80,-9.77,-9.77,94.76,78.93,327.95,327.95,66.35,105.03,107.04,20.71,54.80,-9.77,327.95,320.25,168.70,149.56,88.70,394.29,432.98,2779.20,0.99,1.00,13.00,4.62,6.45,3.80,6.45
15,25,35,3,3.700000000000001,0.0237,0.000571,0.000571,[],0.00337,350.0,12.0,1.00,1.00,170731.7073,400.0,16.0,1.00,1.00,295.0,284552.8455,19.01,[],991.62,993.77,1.82,6.75,0.35,-0.05,0,0.0,0.3,0.1,0,0.0,0.52,0.20,0.32,0.20,107.19,131.78,-20.12,-27.24,70.19,163.79,72.24,108.36,64.59,64.59,-12.80,-12.80,63.24,48.81,163.09,163.09,24.30,35.19,131.78,27.24,64.59,-12.80,163.09,295.57,135.60,127.82,61.61,187.39,198.28,1382.10,1.00,1.00,13.00,4.80,5.59,2.79,5.59
16,6,16,1,4.1,0.0237,0.000571,0.000571,[],0.00337,350.0,12.0,0.90,0.90,170731.7073,400.0,16.0,0.90,0.90,295.0,284552.8455,19.01,[],979.90,986.92,1.82,7.48,0.75,-0.25,0.0,0,0.7,-0.2,0.0,0,0.63,0.24,0.15,0.21,-34.88,-69.76,5.95,11.90,237.39,237.39,193.28,193.28,-25.52,-25.52,4.35,4.35,115.80,94.28,492.81,492.81,122.66,216.19,69.76,11.90,-25.52,4.35,492.81,307.15,205.18,141.32,98.64,615.47,709.01,4176.39,0.99,0.99,13.00,4.06,6.64,4.86,6.64
17,16,26,2,3.75,0.0237,0.000571,0.000571,[],0.00337,350.0,12.0,0.99,0.99,170731.7073,400.0,16.0,0.99,0.99,295.0,284552.8455,19.01,[],986.95,992.11,1.82,6.84,0.4,-0.0,0.0,0.0,0.4,0.1,0.0,0.0,0.88,0.31,0.26,0.30,-107.04,-98.45,20.71,15.93,142.14,213.21,147.99,147.99,-54.80,-54.80,9.77,9.77,94.76,78.93,327.95,327.95,66.35,105.03,107.04,20.71,-54.80,9.77,327.95,320.25,168.70,149.56,88.70,394.29,432.98,2779.20,0.99,1.00,13.00,4.62,6.45,3.80,6.45
18,26,36,3,3.700000000000001,0.0237,0.000571,0.000571,[],0.00337,350.0,12.0,1.00,1.00,170731.7073,400.0,16.0,1.00,1.00,295.0,284552.8455,19.01,[],991.62,993.77,1.82,6.75,0.35,-0.05,0,0.0,0.3,0.1,0,0.0,0.52,0.20,0.32,0.20,-107.19,-131.78,20.12,27.24,70.19,163.79,72.24,108.36,-64.59,-64.59,12.80,12.80,63.24,48.81,163.09,163.09,24.30,35.19,131.78,27.24,-64.59,12.80,163.09,295.57,135.60,127.82,61.61,187.39,198.28,1382.10,1.00,1.00,13.00,4.80,5.59,2.79,5.59
19,7,17,1,4.1,0.0237,0.000571,0.000571,[],0.00337,350.0,12.0,0.90,0.90,170731.7073,400.0,16.0,0.90,0.90,295.0,284552.8455,38.22,[],979.90,994.15,1.82,7.48,0.7,-0.2,0.0,0,0.6,-0.15,0.0,0,1.24,0.38,0.18,0.35,-52.83,-105.66,-0.62,-1.24,281.44,281.44,280.07,342.31,-38.66,-38.66,-0.46,-0.46,137.29,151.80,862.13,862.13,141.89,25.22,105.66,1.24,-38.66,-0.46,862.13,387.11,343.55,175.95,152.26,1004.02,887.35,7306.18,0.99,1.00,13.00,6.15,9.00,8.24,9.00
20,17,27,2,3.75,0.0237,0.000571,0.000571,[],0.00337,350.0,12.0,0.99,0.99,170731.7073,400.0,16.0,0.99,0.99,295.0,284552.8455,38.22,[],986.95,994.15,1.82,6.84,0.4,-0.0,0.0,0.0,0.45,0.05,0.0,0.0,1.75,0.47,0.30,0.46,-161.82,-150.25,-1.18,-1.15,164.83,247.24,226.04,226.04,-83.22,-83.22,-0.62,-0.62,109.89,120.55,583.83,583.83,75.68,13.35,161.82,1.18,-83.22,-0.62,583.83,409.06,227.21,193.10,121.17,659.51,597.18,4947.70,0.99,1.00,13.00,6.54,8.66,5.48,8.66
21,27,37,3,3.700000000000001,0.0237,0.000571,0.000571,[],0.00337,350.0,12.0,1.00,1.00,170731.7073,400.0,16.0,1.00,1.00,295.0,284552.8455,38.22,[],991.62,994.15,1.82,6.75,0.35,-0.05,0,0.0,0.35,0.05,0,0.0,1.02,0.34,0.36,0.34,-169.01,-214.86,-1.09,-2.86,78.85,183.98,119.50,179.26,-103.75,-103.75,-1.07,-1.07,71.03,80.75,302.84,302.84,27.30,3.88,214.86,2.86,-103.75,-1.07,302.84,398.84,182.11,174.79,81.81,330.14,306.72,2566.44,1.00,1.00,13.00,6.88,7.76,3.97,7.76
22,8,18,1,4.1,0.0237,0.000571,0.000571,[],0.00337,350.0,12.0,0.90,0.90,170731.7073,400.0,16.0,0.90,0.90,295.0,284552.8455,38.42,[],979.90,994.15,1.82,7.48,0.7,-0.2,0.0,0,0.6,-0.15,0.0,0,1.24,0.38,0.18,0.34,-53.07,-106.13,0.00,0.00,281.44,281.44,279.16,341.19,-38.83,-38.83,0.00,0.00,137.29,151.30,866.69,866.69,141.89,-0.00,106.13,0.00,-38.83,0.00,866.69,387.58,341.19,176.12,151.30,1008.58,866.69,7344.84,0.99,1.00,13.00,6.15,9.02,8.21,9.02
23,18,28,2,3.75,0.0237,0.000571,0.000571,[],0.00337,350.0,12.0,0.99,0.99,170731.7073,400.0,16.0,0.99,0.99,295.0,284552.8455,38.42,[],986.95,994.15,1.82,6.84,0.4,-0.0,0.0,0.0,0.45,0.05,0.0,0.0,1.74,0.47,0.30,0.46,-162.53,-150.92,0.00,0.00,164.83,247.24,225.40,225.40,-83.59,-83.59,0.00,0.00,109.89,120.21,586.92,586.92,75.68,-0.00,162.53,0.00,-83.59,0.00,586.92,409.78,225.40,193.47,120.21,662.60,586.92,4973.88,0.99,1.00,13.00,6.54,8.68,5.46,8.68
24,28,38,3,3.700000000000001,0.0237,0.000571,0.000571,[],0.00337,350.0,12.0,1.00,1.00,170731.7073,400.0,16.0,1.00,1.00,295.0,284552.8455,38.42,[],991.62,994.15,1.82,6.75,0.35,-0.05,0,0.0,0.35,0.05,0,0.0,1.02,0.34,0.36,0.34,-169.76,-215.82,0.00,0.00,78.85,183.98,119.09,178.63,-104.21,-104.21,0.00,0.00,71.03,80.46,304.44,304.44,27.30,-0.00,215.82,0.00,-104.21,0.00,304.44,399.79,178.63,175.25,80.46,331.74,304.44,2580.02,1.00,1.00,13.00,6.84,7.78,3.91,7.78
25,9,19,1,4.1,0.0237,0.000571,0.000571,[],0.00337,350.0,12.0,0.90,0.90,170731.7073,400.0,16.0,0.90,0.90,295.0,284552.8455,38.22,[],979.90,994.15,1.82,7.48,0.7,-0.2,0.0,0,0.6,-0.15,0.0,0,1.24,0.38,0.18,0.35,-52.83,-105.66,0.62,1.24,281.44,281.44,280.07,342.31,-38.66,-38.66,0.46,0.46,137.29,151.80,862.13,862.13,141.89,-25.22,105.66,1.24,-38.66,0.46,862.13,387.11,343.55,175.95,152.26,1004.02,887.35,7306.18,0.99,1.00,13.00,6.15,9.00,8.24,9.00
26,19,29,2,3.75,0.0237,0.000571,0.000571,[],0.00337,350.0,12.0,0.99,0.99,170731.7073,400.0,16.0,0.99,0.99,295.0,284552.8455,38.22,[],986.95,994.15,1.82,6.84,0.4,-0.0,0.0,0.0,0.45,0.05,0.0,0.0,1.75,0.47,0.30,0.46,-161.82,-150.25,1.18,1.15,164.83,247.24,226.04,226.04,-83.22,-83.22,0.62,0.62,109.89,120.55,583.83,583.83,75.68,-13.35,161.82,1.18,-83.22,0.62,583.83,409.06,227.21,193.10,121.17,659.51,597.18,4947.70,0.99,1.00,13.00,6.54,8.66,5.48,8.66
27,29,39,3,3.700000000000001,0.0237,0.000571,0.000571,[],0.00337,350.0,12.0,1.00,1.00,170731.7073,400.0,16.0,1.00,1.00,295.0,284552.8455,38.22,[],991.62,994.15,1.82,6.75,0.35,-0.05,0,0.0,0.35,0.05,0,0.0,1.02,0.34,0.36,0.34,-169.01,-214.86,1.09,2.86,78.85,183.98,119.50,179.26,-103.75,-103.75,1.07,1.07,71.03,80.75,302.84,302.84,27.30,-3.88,214.86,2.86,-103.75,1.07,302.84,398.84,182.11,174.79,81.81,330.14,306.72,2566.44,1.00,1.00,13.00,6.88,7.76,3.97,7.76
28,10,20,1,4.1,0.0237,0.000571,0.000571,[],0.00337,350.0,12.0,0.90,0.90,170731.7073,400.0,16.0,0.90,0.90,295.0,284552.8455,19.01,[],979.90,986.92,1.82,7.48,0.75,-0.25,0.0,0,0.7,-0.2,0.0,0,0.63,0.24,0.15,0.21,-34.88,-69.76,-5.95,-11.90,237.39,237.39,193.28,193.28,-25.52,-25.52,-4.35,-4.35,115.80,94.28,492.81,492.81,122.66,216.19,69.76,11.90,-25.52,-4.35,492.81,307.15,205.18,141.32,98.64,615.47,709.01,4176.39,0.99,0.99,13.00,4.06,6.64,4.86,6.64
29,20,30,2,3.75,0.0237,0.000571,0.000571,[],0.00337,350.0,12.0,0.99,0.99,170731.7073,400.0,16.0,0.99,0.99,295.0,284552.8455,19.01,[],986.95,992.11,1.82,6.84,0.4,-0.0,0.0,0.0,0.4,0.1,0.0,0.0,0.88,0.31,0.26,0.30,-107.04,-98.45,-20.71,-15.93,142.14,213.21,147.99,147.99,-54.80,-54.80,-9.77,-9.77,94.76,78.93,327.95,327.95,66.35,105.03,107.04,20.71,-54.80,-9.77,327.95,320.25,168.70,149.56,88.70,394.29,432.98,2779.20,0.99,1.00,13.00,4.62,6.45,3.80,6.45
30,30,40,3,3.700000000000001,0.0237,0.000571,0.000571,[],0.00337,350.0,12.0,1.00,1.00,170731.7073,400.0,16.0,1.00,1.00,295.0,284552.8455,19.01,[],991.62,993.77,1.82,6.75,0.35,-0.05,0,0.0,0.3,0.1,0,0.0,0.52,0.20,0.32,0.20,-107.19,-131.78,-20.12,-27.24,70.19,163.79,72.24,108.36,-64.59,-64.59,-12.80,-12.80,63.24,48.81,163.09,163.09,24.30,35.19,131.78,27.24,-64.59,-12.80,163.09,295.57,135.60,127.82,61.61,187.39,198.28,1382.10,1.00,1.00,13.00,4.80,5.59,2.79,5.59
<node_data>
no,x,y,z,beam_no_each_node_x,column_no_each_node_x,column_no_each_node_y,member_no_each_node_x,beam_no_each_node2_x,member_no_each_node2_x,beam_no_each_node_y,beam_no_each_node2_y,member_no_each_node_y,member_no_each_noe2_y,node_member_stiff_x,node_member_stiff_y,node_member_stiff2_x,node_member_stiff2_y,req_Mpx,req_Mpy
1,0.0,0.0,0.0,[],[1],[1],[53],[5],"[5, 53]",[],[1],[53],"[1, 53]","[7.418365392859141e-06, 0.9024390243902441]","[1.773031232451738e-05, 0.9024390243902441]","[1000000000, 0.9024390243902441]","[1000000000, 0.9024390243902441]",0,0
2,0.0,5.64,0.0,[],[4],[4],[56],[10],"[10, 56]",[],"[1, 2]",[56],"[1, 2, 56]","[7.418365392859141e-06, 0.9024390243902441]","[1.773031232451738e-05, 1.7543679375725694e-05, 0.9024390243902441]","[1000000000, 0.9024390243902441]","[1000000000, 1000000000, 0.9024390243902441]",0,0
3,0.0,11.34,0.0,[],[7],[7],[59],[11],"[11, 59]",[],"[2, 3]",[59],"[2, 3, 59]","[7.418365392859141e-06, 0.9024390243902441]","[1.7543679375725694e-05, 1.75436793757257e-05, 0.9024390243902441]","[1000000000, 0.9024390243902441]","[1000000000, 1000000000, 0.9024390243902441]",0,0
4,0.0,17.04,0.0,[],[10],[10],[62],[12],"[12, 62]",[],"[3, 4]",[62],"[3, 4, 62]","[7.418365392859141e-06, 0.9024390243902441]","[1.75436793757257e-05, 1.773031232451738e-05, 0.9024390243902441]","[1000000000, 0.9024390243902441]","[1000000000, 1000000000, 0.9024390243902441]",0,0
5,0.0,22.68,0.0,[],[13],[13],[65],[13],"[13, 65]",[],[4],[65],"[4, 65]","[7.418365392859141e-06, 0.9024390243902441]","[1.773031232451738e-05, 0.9024390243902441]","[1000000000, 0.9024390243902441]","[1000000000, 0.9024390243902441]",0,0
6,13.48,0.0,0.0,[],[16],[16],[68],[5],"[5, 68]",[],[6],[68],"[6, 68]","[7.418365392859141e-06, 0.9024390243902441]","[1.773031232451738e-05, 0.9024390243902441]","[1000000000, 0.9024390243902441]","[1000000000, 0.9024390243902441]",0,0
7,13.48,5.64,0.0,[],[19],[19],[71],[10],"[10, 71]",[],"[6, 7]",[71],"[6, 7, 71]","[7.418365392859141e-06, 0.9024390243902441]","[1.773031232451738e-05, 1.7543679375725694e-05, 0.9024390243902441]","[1000000000, 0.9024390243902441]","[1000000000, 1000000000, 0.9024390243902441]",0,0
8,13.48,11.34,0.0,[],[22],[22],[74],[11],"[11, 74]",[],"[7, 8]",[74],"[7, 8, 74]","[7.418365392859141e-06, 0.9024390243902441]","[1.7543679375725694e-05, 1.75436793757257e-05, 0.9024390243902441]","[1000000000, 0.9024390243902441]","[1000000000, 1000000000, 0.9024390243902441]",0,0
9,13.48,17.04,0.0,[],[25],[25],[77],[12],"[12, 77]",[],"[8, 9]",[77],"[8, 9, 77]","[7.418365392859141e-06, 0.9024390243902441]","[1.75436793757257e-05, 1.773031232451738e-05, 0.9024390243902441]","[1000000000, 0.9024390243902441]","[1000000000, 1000000000, 0.9024390243902441]",0,0
10,13.48,22.68,0.0,[],[28],[28],[80],[13],"[13, 80]",[],[9],[80],"[9, 80]","[7.418365392859141e-06, 0.9024390243902441]","[1.773031232451738e-05, 0.9024390243902441]","[1000000000, 0.9024390243902441]","[1000000000, 0.9024390243902441]",0,0
11,0.0,0.0,4.1,[18],"[1, 2]","[1, 2]","[18, 53, 54]",[18],"[18, 53, 54]",[14],[14],"[14, 53, 54]","[14, 53, 54]","[3.2081865802700906, 0.9024390243902441, 0.9866666666666668]","[0.6804303927244658, 0.9024390243902441, 0.9866666666666668]","[3.2081865802700906, 0.9024390243902441, 0.9866666666666668]","[0.6804303927244658, 0.9024390243902441, 0.9866666666666668]",1413.1779999999999,682.39582
12,0.0,5.64,4.1,[23],"[4, 5]","[4, 5]","[23, 56, 57]",[23],"[23, 56, 57]","[14, 15]","[14, 15]","[14, 15, 56, 57]","[14, 15, 56, 57]","[3.7428843436484396, 0.9024390243902441, 0.9866666666666668]","[0.6804303927244658, 0.6732679675378925, 0.9024390243902441, 0.9866666666666668]","[3.7428843436484396, 0.9024390243902441, 0.9866666666666668]","[0.6804303927244658, 0.6732679675378925, 0.9024390243902441, 0.9866666666666668]",1413.1779999999999,682.39582
13,0.0,11.34,4.1,[24],"[7, 8]","[7, 8]","[24, 59, 60]",[24],"[24, 59, 60]","[15, 16]","[15, 16]","[15, 16, 59, 60]","[15, 16, 59, 60]","[3.7428843436484396, 0.9024390243902441, 0.9866666666666668]","[0.6732679675378925, 0.6732679675378926, 0.9024390243902441, 0.9866666666666668]","[3.7428843436484396, 0.9024390243902441, 0.9866666666666668]","[0.6732679675378925, 0.6732679675378926, 0.9024390243902441, 0.9866666666666668]",1413.1779999999999,682.39582
14,0.0,17.04,4.1,[25],"[10, 11]","[10, 11]","[25, 62, 63]",[25],"[25, 62, 63]","[16, 17]","[16, 17]","[16, 17, 62, 63]","[16, 17, 62, 63]","[3.7428843436484396, 0.9024390243902441, 0.9866666666666668]","[0.6732679675378926, 0.6804303927244657, 0.9024390243902441, 0.9866666666666668]","[3.7428843436484396, 0.9024390243902441, 0.9866666666666668]","[0.6732679675378926, 0.6804303927244657, 0.9024390243902441, 0.9866666666666668]",1413.1779999999999,682.39582
15,0.0,22.68,4.1,[26],"[13, 14]","[13, 14]","[26, 65, 66]",[26],"[26, 65, 66]",[17],[17],"[17, 65, 66]","[17, 65, 66]","[3.2081865802700906, 0.9024390243902441, 0.9866666666666668]","[0.6804303927244657, 0.9024390243902441, 0.9866666666666668]","[3.2081865802700906, 0.9024390243902441, 0.9866666666666668]","[0.6804303927244657, 0.9024390243902441, 0.9866666666666668]",1413.1779999999999,682.39582
16,13.48,0.0,4.1,[18],"[16, 17]","[16, 17]","[18, 68, 69]",[18],"[18, 68, 69]",[19],[19],"[19, 68, 69]","[19, 68, 69]","[3.2081865802700906, 0.9024390243902441, 0.9866666666666668]","[0.6804303927244658, 0.9024390243902441, 0.9866666666666668]","[3.2081865802700906, 0.9024390243902441, 0.9866666666666668]","[0.6804303927244658, 0.9024390243902441, 0.9866666666666668]",1413.1779999999999,682.39582
17,13.48,5.64,4.1,[23],"[19, 20]","[19, 20]","[23, 71, 72]",[23],"[23, 71, 72]","[19, 20]","[19, 20]","[19, 20, 71, 72]","[19, 20, 71, 72]","[3.7428843436484396, 0.9024390243902441, 0.9866666666666668]","[0.6804303927244658, 0.6732679675378925, 0.9024390243902441, 0.9866666666666668]","[3.7428843436484396, 0.9024390243902441, 0.9866666666666668]","[0.6804303927244658, 0.6732679675378925, 0.9024390243902441, 0.9866666666666668]",1413.1779999999999,682.39582
18,13.48,11.34,4.1,[24],"[22, 23]","[22, 23]","[24, 74, 75]",[24],"[24, 74, 75]","[20, 21]","[20, 21]","[20, 21, 74, 75]","[20, 21, 74, 75]","[3.7428843436484396, 0.9024390243902441, 0.9866666666666668]","[0.6732679675378925, 0.6732679675378926, 0.9024390243902441, 0.9866666666666668]","[3.7428843436484396, 0.9024390243902441, 0.9866666666666668]","[0.6732679675378925, 0.6732679675378926, 0.9024390243902441, 0.9866666666666668]",1413.1779999999999,682.39582
19,13.48,17.04,4.1,[25],"[25, 26]","[25, 26]","[25, 77, 78]",[25],"[25, 77, 78]","[21, 22]","[21, 22]","[21, 22, 77, 78]","[21, 22, 77, 78]","[3.7428843436484396, 0.9024390243902441, 0.9866666666666668]","[0.6732679675378926, 0.6804303927244657, 0.9024390243902441, 0.9866666666666668]","[3.7428843436484396, 0.9024390243902441, 0.9866666666666668]","[0.6732679675378926, 0.6804303927244657, 0.9024390243902441, 0.9866666666666668]",1413.1779999999999,682.39582
20,13.48,22.68,4.1,[26],"[28, 29]","[28, 29]","[26, 80, 81]",[26],"[26, 80, 81]",[22],[22],"[22, 80, 81]","[22, 80, 81]","[3.2081865802700906, 0.9024390243902441, 0.9866666666666668]","[0.6804303927244657, 0.9024390243902441, 0.9866666666666668]","[3.2081865802700906, 0.9024390243902441, 0.9866666666666668]","[0.6804303927244657, 0.9024390243902441, 0.9866666666666668]",1413.1779999999999,682.39582
21,0.0,0.0,7.85,[31],"[2, 3]","[2, 3]","[31, 54, 55]",[31],"[31, 54, 55]",[27],[27],"[27, 54, 55]","[27, 54, 55]","[3.2081865802700906, 0.9866666666666668, 1.0]","[0.6804303927244658, 0.9866666666666668, 1.0]","[3.2081865802700906, 0.9866666666666668, 1.0]","[0.6804303927244658, 0.9866666666666668, 1.0]",1413.1779999999999,439.25753499999996
22,0.0,5.64,7.85,[36],"[5, 6]","[5, 6]","[36, 57, 58]",[36],"[36, 57, 58]","[27, 28]","[27, 28]","[27, 28, 57, 58]","[27, 28, 57, 58]","[3.7428843436484396, 0.9866666666666668, 1.0]","[0.6804303927244658, 0.6732679675378925, 0.9866666666666668, 1.0]","[3.7428843436484396, 0.9866666666666668, 1.0]","[0.6804303927244658, 0.6732679675378925, 0.9866666666666668, 1.0]",1413.1779999999999,439.25753499999996
23,0.0,11.34,7.85,[37],"[8, 9]","[8, 9]","[37, 60, 61]",[37],"[37, 60, 61]","[28, 29]","[28, 29]","[28, 29, 60, 61]","[28, 29, 60, 61]","[3.7428843436484396, 0.9866666666666668, 1.0]","[0.6732679675378925, 0.6732679675378926, 0.9866666666666668, 1.0]","[3.7428843436484396, 0.9866666666666668, 1.0]","[0.6732679675378925, 0.6732679675378926, 0.9866666666666668, 1.0]",1413.1779999999999,439.25753499999996
24,0.0,17.04,7.85,[38],"[11, 12]","[11, 12]","[38, 63, 64]",[38],"[38, 63, 64]","[29, 30]","[29, 30]","[29, 30, 63, 64]","[29, 30, 63, 64]","[3.7428843436484396, 0.9866666666666668, 1.0]","[0.6732679675378926, 0.6804303927244657, 0.9866666666666668, 1.0]","[3.7428843436484396, 0.9866666666666668, 1.0]","[0.6732679675378926, 0.6804303927244657, 0.9866666666666668, 1.0]",1413.1779999999999,439.25753499999996
25,0.0,22.68,7.85,[39],"[14, 15]","[14, 15]","[39, 66, 67]",[39],"[39, 66, 67]",[30],[30],"[30, 66, 67]","[30, 66, 67]","[3.2081865802700906, 0.9866666666666668, 1.0]","[0.6804303927244657, 0.9866666666666668, 1.0]","[3.2081865802700906, 0.9866666666666668, 1.0]","[0.6804303927244657, 0.9866666666666668, 1.0]",1413.1779999999999,439.25753499999996
26,13.48,0.0,7.85,[31],"[17, 18]","[17, 18]","[31, 69, 70]",[31],"[31, 69, 70]",[32],[32],"[32, 69, 70]","[32, 69, 70]","[3.2081865802700906, 0.9866666666666668, 1.0]","[0.6804303927244658, 0.9866666666666668, 1.0]","[3.2081865802700906, 0.9866666666666668, 1.0]","[0.6804303927244658, 0.9866666666666668, 1.0]",1413.1779999999999,439.25753499999996
27,13.48,5.64,7.85,[36],"[20, 21]","[20, 21]","[36, 72, 73]",[36],"[36, 72, 73]","[32, 33]","[32, 33]","[32, 33, 72, 73]","[32, 33, 72, 73]","[3.7428843436484396, 0.9866666666666668, 1.0]","[0.6804303927244658, 0.6732679675378925, 0.9866666666666668, 1.0]","[3.7428843436484396, 0.9866666666666668, 1.0]","[0.6804303927244658, 0.6732679675378925, 0.9866666666666668, 1.0]",1413.1779999999999,439.25753499999996
28,13.48,11.34,7.85,[37],"[23, 24]","[23, 24]","[37, 75, 76]",[37],"[37, 75, 76]","[33, 34]","[33, 34]","[33, 34, 75, 76]","[33, 34, 75, 76]","[3.7428843436484396, 0.9866666666666668, 1.0]","[0.6732679675378925, 0.6732679675378926, 0.9866666666666668, 1.0]","[3.7428843436484396, 0.9866666666666668, 1.0]","[0.6732679675378925, 0.6732679675378926, 0.9866666666666668, 1.0]",1413.1779999999999,439.25753499999996
29,13.48,17.04,7.85,[38],"[26, 27]","[26, 27]","[38, 78, 79]",[38],"[38, 78, 79]","[34, 35]","[34, 35]","[34, 35, 78, 79]","[34, 35, 78, 79]","[3.7428843436484396, 0.9866666666666668, 1.0]","[0.6732679675378926, 0.6804303927244657, 0.9866666666666668, 1.0]","[3.7428843436484396, 0.9866666666666668, 1.0]","[0.6732679675378926, 0.6804303927244657, 0.9866666666666668, 1.0]",1413.1779999999999,439.25753499999996
30,13.48,22.68,7.85,[39],"[29, 30]","[29, 30]","[39, 81, 82]",[39],"[39, 81, 82]",[35],[35],"[35, 81, 82]","[35, 81, 82]","[3.2081865802700906, 0.9866666666666668, 1.0]","[0.6804303927244657, 0.9866666666666668, 1.0]","[3.2081865802700906, 0.9866666666666668, 1.0]","[0.6804303927244657, 0.9866666666666668, 1.0]",1413.1779999999999,439.25753499999996
31,0.0,0.0,11.55,[44],[3],[3],"[44, 55]",[44],"[44, 55]",[40],[40],"[40, 55]","[40, 55]","[3.2081865802700906, 1.0]","[0.6804303927244658, 1.0]","[3.2081865802700906, 1.0]","[0.6804303927244658, 1.0]",0,0
32,0.0,5.64,11.55,[49],[6],[6],"[49, 58]",[49],"[49, 58]","[40, 41]","[40, 41]","[40, 41, 58]","[40, 41, 58]","[3.7428843436484396, 1.0]","[0.6804303927244658, 0.6732679675378925, 1.0]","[3.7428843436484396, 1.0]","[0.6804303927244658, 0.6732679675378925, 1.0]",0,0
33,0.0,11.34,11.55,[50],[9],[9],"[50, 61]",[50],"[50, 61]","[41, 42]","[41, 42]","[41, 42, 61]","[41, 42, 61]","[3.7428843436484396, 1.0]","[0.6732679675378925, 0.6732679675378926, 1.0]","[3.7428843436484396, 1.0]","[0.6732679675378925, 0.6732679675378926, 1.0]",0,0
34,0.0,17.04,11.55,[51],[12],[12],"[51, 64]",[51],"[51, 64]","[42, 43]","[42, 43]","[42, 43, 64]","[42, 43, 64]","[3.7428843436484396, 1.0]","[0.6732679675378926, 0.6804303927244657, 1.0]","[3.7428843436484396, 1.0]","[0.6732679675378926, 0.6804303927244657, 1.0]",0,0
35,0.0,22.68,11.55,[52],[15],[15],"[52, 67]",[52],"[52, 67]",[43],[43],"[43, 67]","[43, 67]","[3.2081865802700906, 1.0]","[0.6804303927244657, 1.0]","[3.2081865802700906, 1.0]","[0.6804303927244657, 1.0]",0,0
36,13.48,0.0,11.55,[44],[18],[18],"[44, 70]",[44],"[44, 70]",[45],[45],"[45, 70]","[45, 70]","[3.2081865802700906, 1.0]","[0.6804303927244658, 1.0]","[3.2081865802700906, 1.0]","[0.6804303927244658, 1.0]",0,0
37,13.48,5.64,11.55,[49],[21],[21],"[49, 73]",[49],"[49, 73]","[45, 46]","[45, 46]","[45, 46, 73]","[45, 46, 73]","[3.7428843436484396, 1.0]","[0.6804303927244658, 0.6732679675378925, 1.0]","[3.7428843436484396, 1.0]","[0.6804303927244658, 0.6732679675378925, 1.0]",0,0
38,13.48,11.34,11.55,[50],[24],[24],"[50, 76]",[50],"[50, 76]","[46, 47]","[46, 47]","[46, 47, 76]","[46, 47, 76]","[3.7428843436484396, 1.0]","[0.6732679675378925, 0.6732679675378926, 1.0]","[3.7428843436484396, 1.0]","[0.6732679675378925, 0.6732679675378926, 1.0]",0,0
39,13.48,17.04,11.55,[51],[27],[27],"[51, 79]",[51],"[51, 79]","[47, 48]","[47, 48]","[47, 48, 79]","[47, 48, 79]","[3.7428843436484396, 1.0]","[0.6732679675378926, 0.6804303927244657, 1.0]","[3.7428843436484396, 1.0]","[0.6732679675378926, 0.6804303927244657, 1.0]",0,0
40,13.48,22.68,11.55,[52],[30],[30],"[52, 82]",[52],"[52, 82]",[48],[48],"[48, 82]","[48, 82]","[3.2081865802700906, 1.0]","[0.6804303927244657, 1.0]","[3.2081865802700906, 1.0]","[0.6804303927244657, 1.0]",0,0
<layer_data>
story,height(m),shear_force_x(kN),shear_force_y(kN),omega1,omega2,omega1_seismic,omega2_seismic,floor_area(m2),outerwall_length(m),weight(kN),cum_weight(kN),alpha_i,Ai,Ci,Qi(kN),horizontal_disp_x(mm),horizontal_disp_y(mm),"horizontal_angle_x(rad),",horizontal_angle_y(rad),column_num,req_D_sum_x,req_D_sum_y,req_D_x,req_D_y,D_sum_x,D_sum_y,D_max_x,D_max_y,k_limit1_x,k_limit1_y,I_limit1_x(m4),I_limit1_y(m4)
3,3.70,679.16,679.16,7.65,1.00,7.30,1.00,305.73,72.32,2472.60,2472.60,0.37,1.44,0.29,679.16,11.11,13.26,332.95,278.94,[],2.04,2.04,0.21,0.24,3.40,2.85,0.36,0.34,0.21,0.24,7.906216796468366e-05,9.008490563194613e-05
2,3.75,1038.35,1038.35,6.80,1.00,5.80,1.00,305.73,72.32,2348.33,4820.93,0.69,1.18,0.24,1038.35,20.65,14.95,181.59,250.76,[],3.17,3.17,0.34,0.37,2.87,3.97,0.30,0.46,0.34,0.37,0.00012563163307671553,0.00013832266873438373
1,4.10,1286.94,1286.94,6.70,1.00,5.70,1.00,305.73,72.32,2332.22,7153.15,1.00,1.00,0.20,1286.94,53.06,29.97,77.27,136.78,[],4.29,4.29,0.46,0.51,1.66,2.93,0.18,0.35,0.46,0.51,0.00018762892158986745,0.0002084885067978547